Workbook

Sheet Income Statement
A1: Indian FMCG Sector — Income Statement
A3: Hindustan Unilever Ltd. (Consolidated)
A4: Particulars (₹ Crore) | B4: FY2022 | C4: FY2023 | D4: FY2024 | E4: FY2025 | F4: FY2026
A5: Revenue | B5: 52446 | C5: 60580 | D5: 61896 | E5: 61328 | F5: 64468
A6: Cost of Revenue | B6: 25944 | C6: 31939 | D6: 29987 | E6: 29961 | F6: 31858
A7: Gross Profit | B7: 26502 | C7: 28641 | D7: 31909 | E7: 31367 | F7: 32610
A8: Selling, General & Admin | B8: 7390 | C8: 7864 | D8: 9612 | E8: 8975 | F8: 9473
A9: Other Operating Expenses | B9: 7365 | C9: 7790 | D9: 8883 | E9: 8973 | F9: 9453
A10: Operating Income (EBIT) | B10: 11747 | C10: 12987 | D10: 13414 | E10: 13419 | F10: 13684
A11: Interest Expense | B11: -82 | C11: -88 | D11: -281 | E11: -331 | F11: -334
A12: Interest & Investment Income | B12: 199 | C12: 413 | D12: 549 | E12: 755 | F12: 551
A13: Other Non-Operating Income/(Expense) | B13: 10 | C13: 32 | D13: 244 | E13: 585 | F13: -89
A14: Pretax Income | B14: 11874 | C14: 13344 | D14: 13926 | E14: 14428 | F14: 13812
A15: Income Tax Expense | B15: 2987 | C15: 3201 | D15: 3644 | E15: 3748 | F15: 3160
A16: Net Income | B16: 8879 | C16: 10120 | D16: 10277 | E16: 10649 | F16: 15040
... A18: EPS - Diluted (₹) | B18: 37.79 | C18: 43.07 | D18: 43.74 | E18: 45.32 | F18: 64
A20: Britannia Industries Ltd. (Consolidated)
A21: Particulars (₹ Crore) | B21: FY2022 | C21: FY2023 | D21: FY2024 | E21: FY2025 | F21: FY2026
A22: Revenue | B22: 14136 | C22: 16300 | D22: 16769 | E22: 17942 | F22: 18764
A23: Cost of Revenue | B23: 11935 | C23: 13470 | D23: 13600 | E23: 14755 | F23: 15295
A24: Gross Profit (Operating Profit excl. Other Income) | B24: 2201 | C24: 2830 | D24: 3169 | E24: 3187 | F24: 3469
A25: Interest & Other Income | B25: 222 | C25: 215 | D25: 214 | E25: 227 | F25: 240
A26: EBITDA | B26: 2423 | C26: 3045 | D26: 3383 | E26: 3414 | F26: 3709
A27: Depreciation & Amortization | B27: 200 | C27: 225 | D27: 300 | E27: 313 | F27: 347
A28: Operating Income (EBIT) | B28: 2223 | C28: 2820 | D28: 3083 | E28: 3101 | F28: 3362
A29: Interest Expense | B29: -144 | C29: -169 | D29: -164 | E29: -138 | F29: -111
A30: Pretax Income (recurring) | B30: 2079 | C30: 2651 | D30: 2919 | E30: 2963 | F30: 3251
A31: Income Tax Expense | B31: 562 | C31: 716 | D31: 779 | E31: 748 | F31: 689
A32: Net Income | B32: 1516 | C32: 2310 | D32: 2137 | E32: 2188 | F32: 2562
A33: EPS - Diluted (₹) | B33: 63.31 | C33: 96.39 | D33: 88.84 | E33: 90.45 | F33: 106.35
A35: Nestlé India Ltd.
A36: Particulars (₹ Crore) | B36: FY2022 | C36: FY2023 | D36: FY2024 | E36: FY2025 | F36: FY2026
A37: Revenue | B37: 14741 | C37: 16897 | D37: 24394 | E37: 20202 | F37: 23155
A38: Operating Profit (excl. Other Income) | B38: 3562 | C38: 3706 | D38: 5843 | E38: 4747 | F38: 5261
A39: Other Income | B39: -112 | C39: 107 | D39: 159 | E39: 245 | F39: 160
A40: EBITDA | B40: 3450 | C40: 3813 | D40: 6002 | E40: 4992 | F40: 5421
A41: Depreciation & Amortization | B41: 391 | C41: 403 | D41: 538 | E41: 540 | F41: 699
A42: Operating Income (EBIT) | B42: 3171 | C42: 3303 | D42: 5305 | E42: 4207 | F42: 4562
A43: Interest Expense | B43: -202 | C43: -155 | D43: -145 | E43: -136 | F43: -158
A44: Pretax Income | B44: 2857 | C44: 3255 | D44: 5319 | E44: 4316 | F44: 4564
...

Sheet Balance Sheet
A1: Indian FMCG Sector — Balance Sheet
A3: Hindustan Unilever Ltd. (Consolidated)
A4: Particulars (₹ Crore) | B4: FY2022 | C4: FY2023 | D4: FY2024 | E4: FY2025 | F4: FY2026
A5: Cash & Short-Term Investments | B5: 7142 | C5: 7265 | D5: 11889 | E5: 11053 | F5: 6993
A6: Receivables | B6: 2901 | C6: 3865 | D6: 3365 | E6: 4298 | F6: 3945
A7: Inventory | B7: 4096 | C7: 4251 | D7: 4022 | E7: 4415 | F7: 4789
A8: Other Current Assets | B8: 1383 | C8: 1617 | D8: 2048 | E8: 2285 | F8: 3009
A9: Total Current Assets | B9: 15522 | C9: 16998 | D9: 21324 | E9: 22051 | F9: 19021
A10: Property, Plant & Equipment | B10: 7482 | C10: 8081 | D10: 9056 | E10: 9634 | F10: 9062
A11: Goodwill | B11: 17397 | C11: 17466 | D11: 17466 | E11: 17466 | F11: 18062
A12: Other Intangible Assets | B12: 27907 | C12: 28263 | D12: 28247 | E12: 28244 | F12: 31184
A13: Other Long-Term Assets | B13: 2094 | C13: 2181 | D13: 2304 | E13: 2398 | F13: 2338
A14: Total Assets | B14: 70517 | C14: 73087 | D14: 78499 | E14: 79880 | F14: 79752
A15: Accounts Payable | B15: 9327 | C15: 9859 | D15: 10563 | E15: 11378 | F15: 13385
A16: Short-Term Debt & Current Portion of LT Debt | B16: 30 | C16: 41 | D16: 38 | E16: 41 | F16: 37
... A23: Total Liabilities & Equity | B23: 70517 | C23: 73087 | D23: 78499 | E23: 79880 | F23: 79752
A25: Britannia Industries Ltd. (Consolidated)
A26: Particulars (₹ Crore) | B26: FY2022 | C26: FY2023 | D26: FY2024 | E26: FY2025 | F26: FY2026
A27: Cash & Bank Balances | B27: 185 | C27: 198 | D27: 446 | E27: 312 | F27: 352
A28: Trade Receivables | B28: 332 | C28: 329 | D28: 393 | E28: 449 | F28: 469
A29: Inventories | B29: 1367 | C29: 1193 | D29: 1181 | E29: 1237 | F29: 1346
A30: Investments | B30: 2052 | C30: 3590 | D30: 2919 | E30: 3007 | F30: 3761
A31: Net Fixed Assets (incl. CWIP) | B31: 2275 | C31: 2720 | D31: 2931 | E31: 2964 | F31: 2861
A32: Total Assets | B32: 7476 | C32: 9295 | D32: 9030 | E32: 8802 | F32: 9689
A33: Total Debt | B33: 2466 | C33: 2981 | D33: 2041 | E33: 1225 | F33: 1358
A34: Other Liabilities (incl. current liabilities & provisions) | B34: 2425 | C34: 2750 | D34: 3022 | E34: 3196 | F34: 3195
A35: Total Liabilities | B35: 4891 | C35: 5731 | D35: 5063 | E35: 4421 | F35: 4553
A36: Shareholders' Funds | B36: 2558 | C36: 3534 | D36: 3942 | E36: 4356 | F36: 5107
A37: Minority Interest | B37: 28 | C37: 30 | D37: 25 | E37: 26 | F37: 29
A38: Total Equity (incl. minority interest) | B38: 2586 | C38: 3564 | D38: 3966 | E38: 4381 | F38: 5136
A39: Total Liabilities & Equity | B39: 7476 | C39: 9295 | D39: 9030 | E39: 8802 | F39: 9689
A41: Nestlé India Ltd.
A42: Particulars (₹ Crore) | B42: FY2022 | C42: FY2023 | D42: FY2024 | E42: FY2025 | F42: FY2026
A43: Net Fixed Assets (incl. CWIP) | B43: 3241 | C43: 3402 | D43: 5202 | E43: 6647 | F43: 6797
A44: Investments | B44: 774 | C44: 778 | D44: 464 | E44: 575 | F44: 531
A45: Other Assets (incl. cash, receivables, inventory) | B45: 1503 | C45: 1772 | D45: 4857 | E45: 4972 | F45: 5854
A46: Total Assets | B46: 5518 | C46: 5952 | D46: 10523 | E46: 12193 | F46: 13182
A47: Total Debt | B47: 266 | C47: 271 | D47: 345 | E47: 1167 | F47: 444
A48: Other Liabilities (incl. current liabilities & provisions) | B48: 3305 | C48: 3223 | D48: 6837 | E48: 7016 | F48: 7581
A49: Total Liabilities | B49: 3571 | C49: 3494 | D49: 7182 | E49: 8183 | F49: 8025
...

Sheet Cash Flow
A1: Indian FMCG Sector — Cash Flow Statement
A3: Hindustan Unilever Ltd. (Consolidated)
A4: Particulars (₹ Crore) | B4: FY2022 | C4: FY2023 | D4: FY2024 | E4: FY2025 | F4: FY2026
A5: Net Income | B5: 8879 | C5: 10120 | D5: 10277 | E5: 10649 | F5: 15040
A6: Depreciation & Amortization | B6: 1084 | C6: 1132 | D6: 1207 | E6: 1345 | F6: 1415
A7: Change in Working Capital | B7: -1000 | C7: -960 | D7: 1313 | E7: -788 | F7: 686
A8: Operating Cash Flow | B8: 9048 | C8: 9991 | D8: 15469 | E8: 11886 | F8: 10999
A9: Capital Expenditures | B9: -1225 | C9: -1174 | D9: -1468 | E9: -1254 | F9: -1258
A10: Other Investing Activities | B10: -503 | C10: -320 | D10: -3856 | E10: 7727 | F10: -2426
A11: Investing Cash Flow | B11: -1728 | C11: -1494 | D11: -5324 | E11: 6473 | F11: -3684
A12: Debt Repaid (net) | B12: -352 | C12: -389 | D12: -508 | E12: -498 | F12: -553
A13: Dividends Paid | B13: -7519 | C13: -8474 | D13: -9398 | E13: -12453 | F13: -10103
A14: Other Financing Activities | B14: -144 | C14: -90 | D14: -128 | E14: -150 | F14: -154
A15: Financing Cash Flow | B15: -8015 | C15: -8953 | D15: -10034 | E15: -13101 | F15: -10810
A16: Net Change in Cash | B16: -695 | C16: -446 | D16: 111 | E16: 5258 | F16: -3487
A17: Free Cash Flow | B17: 7823 | C17: 8817 | D17: 14001 | E17: 10632 | F17: 9741
A19: Britannia Industries Ltd. (Consolidated)
A20: Particulars (₹ Crore) | B20: FY2022 | C20: FY2023 | D20: FY2024 | E20: FY2025 | F20: FY2026
A21: Profit Before Tax | B21: 2078 | C21: 3027 | D21: 2916 | E21: 2937 | F21: 3318
A22: Operating Cash Flow | B22: 1299 | C22: 2526 | D22: 2572 | E22: 2490 | F22: 2611
A23: Investing Cash Flow | B23: 914 | C23: -1507 | D23: 485 | E23: 69 | F23: -741
A24: Financing Cash Flow | B24: -2245 | C24: -1028 | D24: -2839 | E24: -2753 | F24: -1782
A25: Net Change in Cash | B25: -32 | C25: -9 | D25: 219 | E25: -194 | F25: 87
A26: Closing Cash & Cash Equivalents | B26: 109 | C26: 100 | D26: 319 | E26: 125 | F26: 212
A28: Nestlé India Ltd.
A29: Particulars (₹ Crore) | B29: FY2022 | C29: FY2023 | D29: FY2024 | E29: FY2025 | F29: FY2026
A30: Operating Cash Flow | B30: 2236 | C30: 2737 | D30: 4175 | E30: 2936 | F30: 5048
A31: Investing Cash Flow | B31: -1920 | C31: -392 | D31: -1237 | E31: -1811 | F31: -624
A32: Financing Cash Flow | B32: -2020 | C32: -2123 | D32: -3135 | E32: -1848 | F32: -3179
A33: Net Change in Cash | B33: -1704 | C33: 223 | D33: -198 | E33: -723 | F33: 1244
A34: Free Cash Flow | B34: 1505 | C34: 2197 | D34: 2296 | E34: 932 | F34: 4221
A36: Notes:
A37: 1. HUL: consolidated, from stockanalysis.com (S&P Global Market Intelligence).
A38: 2. Britannia: consolidated, from Motilal Oswal MarketsMojo; capital expenditure was not separately disclosed by this source (it is embedded within Investing Cash Flow), so Operating/Investing/Financing Cash Flow and Net Change in Cash are shown as reported rather than a fully itemised build-up.
A39: 3. Nestlé India: FY2022/FY2023 are standalone (calendar years 2021/2022); FY2024 is the 15-month transition period (Jan 2023-Mar 2024, consolidated); FY2025/FY2026 are consolidated 12-month years — see Income Statement notes.
A40: 4. Aggregated from third-party data providers; reconcile against each company's audited Annual Report / cash flow statement for statutory use.

Sheet Ratio Comparison
A1: Indian FMCG Sector — Key Financial Ratio Comparison
A3: Revenue (Rs. Crore)
A4: Company | B4: FY2022 | C4: FY2023 | D4: FY2024 | E4: FY2025 | F4: FY2026
A5: Hindustan Unilever | B5: ='Income Statement'!B5 -> 52446 | C5: ='Income Statement'!C5 -> 60580 | D5: ='Income Statement'!D5 -> 61896 | E5: ='Income Statement'!E5 -> 61328 | F5: ='Income Statement'!F5 -> 64468
A6: Britannia Industries | B6: ='Income Statement'!B22 -> 14136 | C6: ='Income Statement'!C22 -> 16300 | D6: ='Income Statement'!D22 -> 16769 | E6: ='Income Statement'!E22 -> 17942 | F6: ='Income Statement'!F22 -> 18764
A7: Nestle India | B7: ='Income Statement'!B37 -> 14741 | C7: ='Income Statement'!C37 -> 16897 | D7: ='Income Statement'!D37 -> 24394 | E7: ='Income Statement'!E37 -> 20202 | F7: ='Income Statement'!F37 -> 23155
A9: Revenue Growth YoY (%)
A10: Company | B10: FY2022 | C10: FY2023 | D10: FY2024 | E10: FY2025 | F10: FY2026
A11: Hindustan Unilever | B11: n/a | C11: =('Income Statement'!C5/'Income Statement'!B5)-1 -> 0.15509286 | D11: =('Income Statement'!D5/'Income Statement'!C5)-1 -> 0.021723341 | E11: =('Income Statement'!E5/'Income Statement'!D5)-1 -> -0.0091766835 | F11: =('Income Statement'!F5/'Income Statement'!E5)-1 -> 0.051200104
A12: Britannia Industries | B12: n/a | C12: =('Income Statement'!C22/'Income Statement'!B22)-1 -> 0.15308432 | D12: =('Income Statement'!D22/'Income Statement'!C22)-1 -> 0.028773006 | E12: =('Income Statement'!E22/'Income Statement'!D22)-1 -> 0.069950504 | F12: =('Income Statement'!F22/'Income Statement'!E22)-1 -> 0.04581429
A13: Nestle India | B13: n/a | C13: =('Income Statement'!C37/'Income Statement'!B37)-1 -> 0.14625873 | D13: =('Income Statement'!D37/'Income Statement'!C37)-1 -> 0.44368823 | E13: =('Income Statement'!E37/'Income Statement'!D37)-1 -> -0.17184554 | F13: =('Income Statement'!F37/'Income Statement'!E37)-1 -> 0.14617365
A15: EBITDA Margin (%)
A16: Company | B16: FY2022 | C16: FY2023 | D16: FY2024 | E16: FY2025 | F16: FY2026
A17: Hindustan Unilever | B17: ='Income Statement'!B17/'Income Statement'!B5 -> 0.23649087 | C17: ='Income Statement'!C17/'Income Statement'!C5 -> 0.22585012 | D17: ='Income Statement'!D17/'Income Statement'!D5 -> 0.22875469 | E17: ='Income Statement'!E17/'Income Statement'!E5 -> 0.23209627 | F17: ='Income Statement'!F17/'Income Statement'!F5 -> 0.22575541
A18: Britannia Industries | B18: ='Income Statement'!B26/'Income Statement'!B22 -> 0.17140634 | C18: ='Income Statement'!C26/'Income Statement'!C22 -> 0.18680982 | D18: ='Income Statement'!D26/'Income Statement'!D22 -> 0.20174131 | E18: ='Income Statement'!E26/'Income Statement'!E22 -> 0.19027979 | F18: ='Income Statement'!F26/'Income Statement'!F22 -> 0.19766574
A19: Nestle India | B19: ='Income Statement'!B40/'Income Statement'!B37 -> 0.23404111 | C19: ='Income Statement'!C40/'Income Statement'!C37 -> 0.22566136 | D19: ='Income Statement'!D40/'Income Statement'!D37 -> 0.24604411 | E19: ='Income Statement'!E40/'Income Statement'!E37 -> 0.24710425 | F19: ='Income Statement'!F40/'Income Statement'!F37 -> 0.2341179
A21: EBIT / Operating Margin (%)
A22: Company | B22: FY2022 | C22: FY2023 | D22: FY2024 | E22: FY2025 | F22: FY2026
A23: Hindustan Unilever | B23: ='Income Statement'!B10/'Income Statement'!B5 -> 0.22398276 | C23: ='Income Statement'!C10/'Income Statement'!C5 -> 0.21437768 | D23: ='Income Statement'!D10/'Income Statement'!D5 -> 0.21671837 | E23: ='Income Statement'!E10/'Income Statement'!E5 -> 0.21880707 | F23: ='Income Statement'!F10/'Income Statement'!F5 -> 0.21226035
A24: Britannia Industries | B24: ='Income Statement'!B28/'Income Statement'!B22 -> 0.15725806 | C24: ='Income Statement'!C28/'Income Statement'!C22 -> 0.17300613 | D24: ='Income Statement'!D28/'Income Statement'!D22 -> 0.18385115 | E24: ='Income Statement'!E28/'Income Statement'!E22 -> 0.17283469 | F24: ='Income Statement'!F28/'Income Statement'!F22 -> 0.17917288
A25: Nestle India | B25: ='Income Statement'!B42/'Income Statement'!B37 -> 0.21511431 | C25: ='Income Statement'!C42/'Income Statement'!C37 -> 0.19547849 | D25: ='Income Statement'!D42/'Income Statement'!D37 -> 0.21747151 | E25: ='Income Statement'!E42/'Income Statement'!E37 -> 0.20824671 | F25: ='Income Statement'!F42/'Income Statement'!F37 -> 0.19702008
A27: Net Profit Margin (%)
A28: Company | B28: FY2022 | C28: FY2023 | D28: FY2024 | E28: FY2025 | F28: FY2026
A29: Hindustan Unilever | B29: ='Income Statement'!B16/'Income Statement'!B5 -> 0.16929794 | C29: ='Income Statement'!C16/'Income Statement'!C5 -> 0.16705183 | D29: ='Income Statement'!D16/'Income Statement'!D5 -> 0.16603658 | E29: ='Income Statement'!E16/'Income Statement'!E5 -> 0.1736401 | F29: ='Income Statement'!F16/'Income Statement'!F5 -> 0.23329404
A30: Britannia Industries | B30: ='Income Statement'!B32/'Income Statement'!B22 -> 0.10724392 | C30: ='Income Statement'!C32/'Income Statement'!C22 -> 0.14171779 | D30: ='Income Statement'!D32/'Income Statement'!D22 -> 0.12743753 | E30: ='Income Statement'!E32/'Income Statement'!E22 -> 0.1219485 | F30: ='Income Statement'!F32/'Income Statement'!F22 -> 0.13653805
A31: Nestle India | B31: ='Income Statement'!B46/'Income Statement'!B37 -> 0.14368089 | C31: ='Income Statement'!C46/'Income Statement'!C37 -> 0.14150441 | D31: ='Income Statement'!D46/'Income Statement'!D37 -> 0.16122817 | E31: ='Income Statement'!E46/'Income Statement'!E37 -> 0.15879616 | F31: ='Income Statement'!F46/'Income Statement'!F37 -> 0.15111207
A33: Return on Equity - ROE (%)
A34: Company | B34: FY2022 | C34: FY2023 | D34: FY2024 | E34: FY2025 | F34: FY2026
A35: Hindustan Unilever | B35: ='Income Statement'!B16/'Balance Sheet'!B22 -> 0.18088292 | C35: ='Income Statement'!C16/'Balance Sheet'!C22 -> 0.20030878 | D35: ='Income Statement'!D16/'Balance Sheet'!D22 -> 0.19985221 | E35: ='Income Statement'!E16/'Balance Sheet'!E22 -> 0.21465863 | F35: ='Income Statement'!F16/'Balance Sheet'!F22 -> 0.30688867
A36: Britannia Industries | B36: ='Income Statement'!B32/'Balance Sheet'!B36 -> 0.59265051 | C36: ='Income Statement'!C32/'Balance Sheet'!C36 -> 0.65365025 | D36: ='Income Statement'!D32/'Balance Sheet'!D36 -> 0.5421106 | E36: ='Income Statement'!E32/'Balance Sheet'!E36 -> 0.50229568 | F36: ='Income Statement'!F32/'Balance Sheet'!F36 -> 0.50166438
A37: Nestle India | B37: ='Income Statement'!B46/'Balance Sheet'!B50 -> 1.0883864 | C37: ='Income Statement'!C46/'Balance Sheet'!C50 -> 0.97234648 | D37: ='Income Statement'!D46/'Balance Sheet'!D50 -> 1.1771925 | E37: ='Income Statement'!E46/'Balance Sheet'!E50 -> 0.8 | F37: ='Income Statement'!F46/'Balance Sheet'!F50 -> 0.67849525
A39: Return on Assets - ROA (%)
A40: Company | B40: FY2022 | C40: FY2023 | D40: FY2024 | E40: FY2025 | F40: FY2026
A41: Hindustan Unilever | B41: ='Income Statement'!B16/'Balance Sheet'!B14 -> 0.1259129 | C41: ='Income Statement'!C16/'Balance Sheet'!C14 -> 0.13846512 | D41: ='Income Statement'!D16/'Balance Sheet'!D14 -> 0.13091887 | E41: ='Income Statement'!E16/'Balance Sheet'!E14 -> 0.13331247 | F41: ='Income Statement'!F16/'Balance Sheet'!F14 -> 0.18858461
A42: Britannia Industries | B42: ='Income Statement'!B32/'Balance Sheet'!B32 -> 0.20278224 | C42: ='Income Statement'!C32/'Balance Sheet'!C32 -> 0.24852071 | D42: ='Income Statement'!D32/'Balance Sheet'!D32 -> 0.23665559 | E42: ='Income Statement'!E32/'Balance Sheet'!E32 -> 0.24857987 | F42: ='Income Statement'!F32/'Balance Sheet'!F32 -> 0.26442357
A43: Nestle India | B43: ='Income Statement'!B46/'Balance Sheet'!B46 -> 0.38383472 | C43: ='Income Statement'!C46/'Balance Sheet'!C46 -> 0.40171371 | D43: ='Income Statement'!D46/'Balance Sheet'!D46 -> 0.37375273 | E43: ='Income Statement'!E46/'Balance Sheet'!E46 -> 0.26310178 | F43: ='Income Statement'!F46/'Balance Sheet'!F46 -> 0.26543772
A45: Operating Cash Flow Margin (%)
A46: Company | B46: FY2022 | C46: FY2023 | D46: FY2024 | E46: FY2025 | F46: FY2026
A47: Hindustan Unilever | B47: ='Cash Flow'!B8/'Income Statement'!B5 -> 0.17252031 | C47: ='Cash Flow'!C8/'Income Statement'!C5 -> 0.16492242 | D47: ='Cash Flow'!D8/'Income Statement'!D5 -> 0.24991922 | E47: ='Cash Flow'!E8/'Income Statement'!E5 -> 0.19381033 | F47: ='Cash Flow'!F8/'Income Statement'!F5 -> 0.17061178
A48: Britannia Industries | B48: ='Cash Flow'!B22/'Income Statement'!B22 -> 0.091893039 | C48: ='Cash Flow'!C22/'Income Statement'!C22 -> 0.15496933 | D48: ='Cash Flow'!D22/'Income Statement'!D22 -> 0.15337826 | E48: ='Cash Flow'!E22/'Income Statement'!E22 -> 0.13878051 | F48: ='Cash Flow'!F22/'Income Statement'!F22 -> 0.13914944
...

Sheet Pivot Tables
A1: Pivot Tables — Ratio Data by Company & Year
A3: PIVOT SOURCE DATA
A4: Company | B4: Fiscal Year | C4: Ratio | D4: Value
A5: Hindustan Unilever | B5: FY2022 | C5: Revenue (Rs. Crore) | D5: ='Ratio Comparison'!B5 -> 52446
A6: Hindustan Unilever | B6: FY2023 | C6: Revenue (Rs. Crore) | D6: ='Ratio Comparison'!C5 -> 60580
A7: Hindustan Unilever | B7: FY2024 | C7: Revenue (Rs. Crore) | D7: ='Ratio Comparison'!D5 -> 61896
A8: Hindustan Unilever | B8: FY2025 | C8: Revenue (Rs. Crore) | D8: ='Ratio Comparison'!E5 -> 61328
A9: Hindustan Unilever | B9: FY2026 | C9: Revenue (Rs. Crore) | D9: ='Ratio Comparison'!F5 -> 64468
A10: Britannia Industries | B10: FY2022 | C10: Revenue (Rs. Crore) | D10: ='Ratio Comparison'!B6 -> 14136
A11: Britannia Industries | B11: FY2023 | C11: Revenue (Rs. Crore) | D11: ='Ratio Comparison'!C6 -> 16300
A12: Britannia Industries | B12: FY2024 | C12: Revenue (Rs. Crore) | D12: ='Ratio Comparison'!D6 -> 16769
A13: Britannia Industries | B13: FY2025 | C13: Revenue (Rs. Crore) | D13: ='Ratio Comparison'!E6 -> 17942
A14: Britannia Industries | B14: FY2026 | C14: Revenue (Rs. Crore) | D14: ='Ratio Comparison'!F6 -> 18764
A15: Nestle India | B15: FY2022 | C15: Revenue (Rs. Crore) | D15: ='Ratio Comparison'!B7 -> 14741
A16: Nestle India | B16: FY2023 | C16: Revenue (Rs. Crore) | D16: ='Ratio Comparison'!C7 -> 16897
A17: Nestle India | B17: FY2024 | C17: Revenue (Rs. Crore) | D17: ='Ratio Comparison'!D7 -> 24394
A18: Nestle India | B18: FY2025 | C18: Revenue (Rs. Crore) | D18: ='Ratio Comparison'!E7 -> 20202
A19: Nestle India | B19: FY2026 | C19: Revenue (Rs. Crore) | D19: ='Ratio Comparison'!F7 -> 23155
A20: Hindustan Unilever | B20: FY2022 | C20: Revenue Growth YoY (%) | D20: n/a
A21: Hindustan Unilever | B21: FY2023 | C21: Revenue Growth YoY (%) | D21: ='Ratio Comparison'!C11 -> 0.15509286
A22: Hindustan Unilever | B22: FY2024 | C22: Revenue Growth YoY (%) | D22: ='Ratio Comparison'!D11 -> 0.021723341
A23: Hindustan Unilever | B23: FY2025 | C23: Revenue Growth YoY (%) | D23: ='Ratio Comparison'!E11 -> -0.0091766835
A24: Hindustan Unilever | B24: FY2026 | C24: Revenue Growth YoY (%) | D24: ='Ratio Comparison'!F11 -> 0.051200104
A25: Britannia Industries | B25: FY2022 | C25: Revenue Growth YoY (%) | D25: n/a
A26: Britannia Industries | B26: FY2023 | C26: Revenue Growth YoY (%) | D26: ='Ratio Comparison'!C12 -> 0.15308432
A27: Britannia Industries | B27: FY2024 | C27: Revenue Growth YoY (%) | D27: ='Ratio Comparison'!D12 -> 0.028773006
A28: Britannia Industries | B28: FY2025 | C28: Revenue Growth YoY (%) | D28: ='Ratio Comparison'!E12 -> 0.069950504
A29: Britannia Industries | B29: FY2026 | C29: Revenue Growth YoY (%) | D29: ='Ratio Comparison'!F12 -> 0.04581429
A30: Nestle India | B30: FY2022 | C30: Revenue Growth YoY (%) | D30: n/a
A31: Nestle India | B31: FY2023 | C31: Revenue Growth YoY (%) | D31: ='Ratio Comparison'!C13 -> 0.14625873
A32: Nestle India | B32: FY2024 | C32: Revenue Growth YoY (%) | D32: ='Ratio Comparison'!D13 -> 0.44368823
A33: Nestle India | B33: FY2025 | C33: Revenue Growth YoY (%) | D33: ='Ratio Comparison'!E13 -> -0.17184554
A34: Nestle India | B34: FY2026 | C34: Revenue Growth YoY (%) | D34: ='Ratio Comparison'!F13 -> 0.14617365
A35: Hindustan Unilever | B35: FY2022 | C35: EBITDA Margin (%) | D35: ='Ratio Comparison'!B17 -> 0.23649087
A36: Hindustan Unilever | B36: FY2023 | C36: EBITDA Margin (%) | D36: ='Ratio Comparison'!C17 -> 0.22585012
A37: Hindustan Unilever | B37: FY2024 | C37: EBITDA Margin (%) | D37: ='Ratio Comparison'!D17 -> 0.22875469
A38: Hindustan Unilever | B38: FY2025 | C38: EBITDA Margin (%) | D38: ='Ratio Comparison'!E17 -> 0.23209627
A39: Hindustan Unilever | B39: FY2026 | C39: EBITDA Margin (%) | D39: ='Ratio Comparison'!F17 -> 0.22575541
A40: Britannia Industries | B40: FY2022 | C40: EBITDA Margin (%) | D40: ='Ratio Comparison'!B18 -> 0.17140634
A41: Britannia Industries | B41: FY2023 | C41: EBITDA Margin (%) | D41: ='Ratio Comparison'!C18 -> 0.18680982
...

Sheet Charts
B1: Indian FMCG Sector — Ratio Comparison Charts
B2: All charts are native Excel charts, linked live to the Pivot Tables sheet — they update automatically if source data changes.

Sheet Pivot
A1: Pivot Tables Analysis
A3: Row Labels | B3: Sum of FY2026
A4: Britannia Industries | B4: 0.04581429
A5: Hindustan Unilever | B5: 0.051200104
A6: Nestle India | B6: 0.14617365
A7: Grand Total | B7: 0.24318804
B10: Values
A11: Row Labels | B11: Sum of FY2022 | C11: Sum of FY2023 | D11: Sum of FY2024 | E11: Sum of FY2025 | F11: Sum of FY2026
A12: Britannia Industries | B12: 0.10724392 | C12: 0.14171779 | D12: 0.12743753 | E12: 0.1219485 | F12: 0.13653805
A13: Hindustan Unilever | B13: 0.16929794 | C13: 0.16705183 | D13: 0.16603658 | E13: 0.1736401 | F13: 0.23329404
A14: Nestle India | B14: 0.14368089 | C14: 0.14150441 | D14: 0.16122817 | E14: 0.15879616 | F14: 0.15111207
A15: Grand Total | B15: 0.42022275 | C15: 0.45027403 | D15: 0.45470228 | E15: 0.45438476 | F15: 0.52094416
A17: Row Labels | B17: Sum of FY2022 | C17: Sum of FY2023 | D17: Sum of FY2024 | E17: Sum of FY2025 | F17: Sum of FY2026
A18: Britannia Industries | B18: 0.10724392 | C18: 0.14171779 | D18: 0.12743753 | E18: 0.1219485 | F18: 0.13653805
A19: Hindustan Unilever | B19: 0.16929794 | C19: 0.16705183 | D19: 0.16603658 | E19: 0.1736401 | F19: 0.23329404
A20: Nestle India | B20: 0.14368089 | C20: 0.14150441 | D20: 0.16122817 | E20: 0.15879616 | F20: 0.15111207
A21: Grand Total | B21: 0.42022275 | C21: 0.45027403 | D21: 0.45470228 | E21: 0.45438476 | F21: 0.52094416
A24: Row Labels | B24: Sum of FY2022 | C24: Sum of FY2023 | D24: Sum of FY2024 | E24: Sum of FY2025 | F24: Sum of FY2026
A25: Britannia Industries | B25: 0.59265051 | C25: 0.65365025 | D25: 0.5421106 | E25: 0.50229568 | F25: 0.50166438
A26: Hindustan Unilever | B26: 0.18088292 | C26: 0.20030878 | D26: 0.19985221 | E26: 0.21465863 | F26: 0.30688867
A27: Nestle India | B27: 1.0883864 | C27: 0.97234648 | D27: 1.1771925 | E27: 0.8 | F27: 0.67849525
A28: Grand Total | B28: 1.8619199 | C28: 1.8263055 | D28: 1.9191553 | E28: 1.5169543 | F28: 1.4870483
A31: Row Labels | B31: Sum of FY2022 | C31: Sum of FY2023 | D31: Sum of FY2024 | E31: Sum of FY2025 | F31: Sum of FY2026
A32: Britannia Industries | B32: 0.9640344 | C32: 0.84352009 | D32: 0.51775748 | E32: 0.2812213 | F32: 0.26590954
A33: Hindustan Unilever | B33: 0.015706806 | C33: 0.016784767 | D33: 0.022246855 | E33: 0.0258824 | F33: 0.023281913
A34: Nestle India | B34: 0.13669065 | C34: 0.1102074 | D34: 0.1032625 | E34: 0.29102244 | F34: 0.086096568
A35: Grand Total | B35: 1.1164319 | C35: 0.97051226 | D35: 0.64326683 | E35: 0.59812615 | F35: 0.37528802

Sheet Dashboard
A1: FINANCIAL DASHBORD OF FMCG INDUSTRIES

Sheet Red Flags
A1: FMCG Sector — Financial Red Flag Analysis
A2: Rule-based screening of HUL, Britannia and Nestlé using the existing Ratio Comparison sheet. Flags indicate areas for investigation, not proof of financial problems.
A4: SUMMARY — CURRENT FY2026
A5: Company | B5: Red Flags | C5: Watch Items | D5: Clear Metrics | E5: Overall Screening
A6: Hindustan Unilever | B6: =COUNTIFS($A$11:$A$40,A6,$H$11:$H$40,"RED FLAG") -> 0 | C6: =COUNTIFS($A$11:$A$40,A6,$H$11:$H$40,"WATCH") -> 3 | D6: =COUNTIFS($A$11:$A$40,A6,$H$11:$H$40,"CLEAR") -> 7 | E6: =IF(B6>0,"INVESTIGATE",IF(C6>0,"MONITOR","NO FLAG")) -> MONITOR
A7: Britannia Industries | B7: =COUNTIFS($A$11:$A$40,A7,$H$11:$H$40,"RED FLAG") -> 0 | C7: =COUNTIFS($A$11:$A$40,A7,$H$11:$H$40,"WATCH") -> 2 | D7: =COUNTIFS($A$11:$A$40,A7,$H$11:$H$40,"CLEAR") -> 8 | E7: =IF(B7>0,"INVESTIGATE",IF(C7>0,"MONITOR","NO FLAG")) -> MONITOR
A8: Nestle India | B8: =COUNTIFS($A$11:$A$40,A8,$H$11:$H$40,"RED FLAG") -> 0 | C8: =COUNTIFS($A$11:$A$40,A8,$H$11:$H$40,"WATCH") -> 4 | D8: =COUNTIFS($A$11:$A$40,A8,$H$11:$H$40,"CLEAR") -> 6 | E8: =IF(B8>0,"INVESTIGATE",IF(C8>0,"MONITOR","NO FLAG")) -> MONITOR
A10: Company | B10: Metric | C10: FY2026 Value | D10: Prior FY Value | E10: Change / Test | F10: Threshold | G10: Direction | H10: Status | I10: Why it matters
A11: Hindustan Unilever | B11: Revenue Growth | C11: ='Ratio Comparison'!F11 -> 0.051200104 | D11: ='Ratio Comparison'!E11 -> -0.0091766835 | E11: =C11 -> 0.051200104 | F11: 0 | G11: < 0 | H11: =IF(C11<0,"RED FLAG","CLEAR") -> CLEAR | I11: Revenue contraction
A12: Britannia Industries | B12: Revenue Growth | C12: ='Ratio Comparison'!F12 -> 0.04581429 | D12: ='Ratio Comparison'!E12 -> 0.069950504 | E12: =C12 -> 0.04581429 | F12: 0 | G12: < 0 | H12: =IF(C12<0,"RED FLAG","CLEAR") -> CLEAR | I12: Revenue contraction
A13: Nestle India | B13: Revenue Growth | C13: ='Ratio Comparison'!F13 -> 0.14617365 | D13: ='Ratio Comparison'!E13 -> -0.17184554 | E13: =C13 -> 0.14617365 | F13: 0 | G13: < 0 | H13: =IF(C13<0,"RED FLAG","CLEAR") -> CLEAR | I13: Revenue contraction
A14: Hindustan Unilever | B14: EBITDA Margin | C14: ='Ratio Comparison'!F17 -> 0.22575541 | D14: ='Ratio Comparison'!E17 -> 0.23209627 | E14: =C14-D14 -> -0.0063408557 | F14: 0.02 | G14: < -threshold | H14: =IF(E14<-F14,"RED FLAG",IF(E14<0,"WATCH","CLEAR")) -> WATCH | I14: YoY margin fall >2 percentage points
A15: Britannia Industries | B15: EBITDA Margin | C15: ='Ratio Comparison'!F18 -> 0.19766574 | D15: ='Ratio Comparison'!E18 -> 0.19027979 | E15: =C15-D15 -> 0.0073859525 | F15: 0.02 | G15: < -threshold | H15: =IF(E15<-F15,"RED FLAG",IF(E15<0,"WATCH","CLEAR")) -> CLEAR | I15: YoY margin fall >2 percentage points
A16: Nestle India | B16: EBITDA Margin | C16: ='Ratio Comparison'!F19 -> 0.2341179 | D16: ='Ratio Comparison'!E19 -> 0.24710425 | E16: =C16-D16 -> -0.012986346 | F16: 0.02 | G16: < -threshold | H16: =IF(E16<-F16,"RED FLAG",IF(E16<0,"WATCH","CLEAR")) -> WATCH | I16: YoY margin fall >2 percentage points
A17: Hindustan Unilever | B17: EBIT / Operating Margin | C17: ='Ratio Comparison'!F23 -> 0.21226035 | D17: ='Ratio Comparison'!E23 -> 0.21880707 | E17: =C17-D17 -> -0.006546724 | F17: 0.02 | G17: < -threshold | H17: =IF(E17<-F17,"RED FLAG",IF(E17<0,"WATCH","CLEAR")) -> WATCH | I17: YoY operating-margin fall >2 percentage points
A18: Britannia Industries | B18: EBIT / Operating Margin | C18: ='Ratio Comparison'!F24 -> 0.17917288 | D18: ='Ratio Comparison'!E24 -> 0.17283469 | E18: =C18-D18 -> 0.0063381947 | F18: 0.02 | G18: < -threshold | H18: =IF(E18<-F18,"RED FLAG",IF(E18<0,"WATCH","CLEAR")) -> CLEAR | I18: YoY operating-margin fall >2 percentage points
A19: Nestle India | B19: EBIT / Operating Margin | C19: ='Ratio Comparison'!F25 -> 0.19702008 | D19: ='Ratio Comparison'!E25 -> 0.20824671 | E19: =C19-D19 -> -0.011226626 | F19: 0.02 | G19: < -threshold | H19: =IF(E19<-F19,"RED FLAG",IF(E19<0,"WATCH","CLEAR")) -> WATCH | I19: YoY operating-margin fall >2 percentage points
A20: Hindustan Unilever | B20: Net Profit Margin | C20: ='Ratio Comparison'!F29 -> 0.23329404 | D20: ='Ratio Comparison'!E29 -> 0.1736401 | E20: =C20-D20 -> 0.059653938 | F20: 0.02 | G20: < -threshold | H20: =IF(E20<-F20,"RED FLAG",IF(E20<0,"WATCH","CLEAR")) -> CLEAR | I20: YoY net-margin fall >2 percentage points
A21: Britannia Industries | B21: Net Profit Margin | C21: ='Ratio Comparison'!F30 -> 0.13653805 | D21: ='Ratio Comparison'!E30 -> 0.1219485 | E21: =C21-D21 -> 0.014589551 | F21: 0.02 | G21: < -threshold | H21: =IF(E21<-F21,"RED FLAG",IF(E21<0,"WATCH","CLEAR")) -> CLEAR | I21: YoY net-margin fall >2 percentage points
A22: Nestle India | B22: Net Profit Margin | C22: ='Ratio Comparison'!F31 -> 0.15111207 | D22: ='Ratio Comparison'!E31 -> 0.15879616 | E22: =C22-D22 -> -0.007684088 | F22: 0.02 | G22: < -threshold | H22: =IF(E22<-F22,"RED FLAG",IF(E22<0,"WATCH","CLEAR")) -> WATCH | I22: YoY net-margin fall >2 percentage points
A23: Hindustan Unilever | B23: ROE | C23: ='Ratio Comparison'!F35 -> 0.30688867 | D23: ='Ratio Comparison'!E35 -> 0.21465863 | E23: =C23 -> 0.30688867 | F23: 0.5 | G23: > threshold | H23: =IF(C23>F23,"WATCH","CLEAR") -> CLEAR | I23: Unusually high ROE (>50%) — investigate equity denominator
A24: Britannia Industries | B24: ROE | C24: ='Ratio Comparison'!F36 -> 0.50166438 | D24: ='Ratio Comparison'!E36 -> 0.50229568 | E24: =C24 -> 0.50166438 | F24: 0.5 | G24: > threshold | H24: =IF(C24>F24,"WATCH","CLEAR") -> WATCH | I24: Unusually high ROE (>50%) — investigate equity denominator
A25: Nestle India | B25: ROE | C25: ='Ratio Comparison'!F37 -> 0.67849525 | D25: ='Ratio Comparison'!E37 -> 0.8 | E25: =C25 -> 0.67849525 | F25: 0.5 | G25: > threshold | H25: =IF(C25>F25,"WATCH","CLEAR") -> WATCH | I25: Unusually high ROE (>50%) — investigate equity denominator
A26: Hindustan Unilever | B26: ROA | C26: ='Ratio Comparison'!F41 -> 0.18858461 | D26: ='Ratio Comparison'!E41 -> 0.13331247 | E26: =C26-D26 -> 0.055272144 | F26: 0.03 | G26: < -threshold | H26: =IF(E26<-F26,"RED FLAG",IF(E26<0,"WATCH","CLEAR")) -> CLEAR | I26: YoY ROA fall >3 percentage points
A27: Britannia Industries | B27: ROA | C27: ='Ratio Comparison'!F42 -> 0.26442357 | D27: ='Ratio Comparison'!E42 -> 0.24857987 | E27: =C27-D27 -> 0.015843705 | F27: 0.03 | G27: < -threshold | H27: =IF(E27<-F27,"RED FLAG",IF(E27<0,"WATCH","CLEAR")) -> CLEAR | I27: YoY ROA fall >3 percentage points
A28: Nestle India | B28: ROA | C28: ='Ratio Comparison'!F43 -> 0.26543772 | D28: ='Ratio Comparison'!E43 -> 0.26310178 | E28: =C28-D28 -> 0.0023359384 | F28: 0.03 | G28: < -threshold | H28: =IF(E28<-F28,"RED FLAG",IF(E28<0,"WATCH","CLEAR")) -> CLEAR | I28: YoY ROA fall >3 percentage points
A29: Hindustan Unilever | B29: Operating Cash Flow Margin | C29: ='Ratio Comparison'!F47 -> 0.17061178 | D29: ='Ratio Comparison'!E47 -> 0.19381033 | E29: =C29 -> 0.17061178 | F29: 0.1 | G29: < threshold | H29: =IF(C29<F29,"RED FLAG","CLEAR") -> CLEAR | I29: OCF margin below 10%
A30: Britannia Industries | B30: Operating Cash Flow Margin | C30: ='Ratio Comparison'!F48 -> 0.13914944 | D30: ='Ratio Comparison'!E48 -> 0.13878051 | E30: =C30 -> 0.13914944 | F30: 0.1 | G30: < threshold | H30: =IF(C30<F30,"RED FLAG","CLEAR") -> CLEAR | I30: OCF margin below 10%
A31: Nestle India | B31: Operating Cash Flow Margin | C31: ='Ratio Comparison'!F49 -> 0.21800907 | D31: ='Ratio Comparison'!E49 -> 0.14533215 | E31: =C31 -> 0.21800907 | F31: 0.1 | G31: < threshold | H31: =IF(C31<F31,"RED FLAG","CLEAR") -> CLEAR | I31: OCF margin below 10%
A32: Hindustan Unilever | B32: Operating Cash Flow Margin | C32: ='Ratio Comparison'!F47 -> 0.17061178 | D32: ='Ratio Comparison'!E47 -> 0.19381033 | E32: =C32-D32 -> -0.023198555 | F32: 0.03 | G32: < -threshold | H32: =IF(E32<-F32,"RED FLAG",IF(E32<0,"WATCH","CLEAR")) -> WATCH | I32: YoY OCF-margin fall >3 percentage points
A33: Britannia Industries | B33: Operating Cash Flow Margin | C33: ='Ratio Comparison'!F48 -> 0.13914944 | D33: ='Ratio Comparison'!E48 -> 0.13878051 | E33: =C33-D33 -> 0.0003689201 | F33: 0.03 | G33: < -threshold | H33: =IF(E33<-F33,"RED FLAG",IF(E33<0,"WATCH","CLEAR")) -> CLEAR | I33: YoY OCF-margin fall >3 percentage points
A34: Nestle India | B34: Operating Cash Flow Margin | C34: ='Ratio Comparison'!F49 -> 0.21800907 | D34: ='Ratio Comparison'!E49 -> 0.14533215 | E34: =C34-D34 -> 0.072676924 | F34: 0.03 | G34: < -threshold | H34: =IF(E34<-F34,"RED FLAG",IF(E34<0,"WATCH","CLEAR")) -> CLEAR | I34: YoY OCF-margin fall >3 percentage points
A35: Hindustan Unilever | B35: Debt-to-Equity | C35: ='Ratio Comparison'!F53 -> 0.023281913 | D35: ='Ratio Comparison'!E53 -> 0.0258824 | E35: =C35 -> 0.023281913 | F35: 0.5 | G35: > threshold | H35: =IF(C35>F35,"WATCH","CLEAR") -> CLEAR | I35: Debt-to-equity above 0.50x
A36: Britannia Industries | B36: Debt-to-Equity | C36: ='Ratio Comparison'!F54 -> 0.26590954 | D36: ='Ratio Comparison'!E54 -> 0.2812213 | E36: =C36 -> 0.26590954 | F36: 0.5 | G36: > threshold | H36: =IF(C36>F36,"WATCH","CLEAR") -> CLEAR | I36: Debt-to-equity above 0.50x
A37: Nestle India | B37: Debt-to-Equity | C37: ='Ratio Comparison'!F55 -> 0.086096568 | D37: ='Ratio Comparison'!E55 -> 0.29102244 | E37: =C37 -> 0.086096568 | F37: 0.5 | G37: > threshold | H37: =IF(C37>F37,"WATCH","CLEAR") -> CLEAR | I37: Debt-to-equity above 0.50x
A38: Hindustan Unilever | B38: Asset Turnover | C38: ='Ratio Comparison'!F59 -> 0.8083559 | D38: ='Ratio Comparison'!E59 -> 0.76775163 | E38: =IF(D38=0,0,(C38/D38)-1) -> 0.052887255 | F38: 0.15 | G38: < -threshold | H38: =IF(E38<-F38,"RED FLAG",IF(E38<0,"WATCH","CLEAR")) -> CLEAR | I38: YoY asset-turnover decline >15%
A39: Britannia Industries | B39: Asset Turnover | C39: ='Ratio Comparison'!F60 -> 1.9366292 | D39: ='Ratio Comparison'!E60 -> 2.0384004 | E39: =IF(D39=0,0,(C39/D39)-1) -> -0.049926991 | F39: 0.15 | G39: < -threshold | H39: =IF(E39<-F39,"RED FLAG",IF(E39<0,"WATCH","CLEAR")) -> WATCH | I39: YoY asset-turnover decline >15%
A40: Nestle India | B40: Asset Turnover | C40: ='Ratio Comparison'!F61 -> 1.756562 | D40: ='Ratio Comparison'!E61 -> 1.6568523 | E40: =IF(D40=0,0,(C40/D40)-1) -> 0.06018019 | F40: 0.15 | G40: < -threshold | H40: =IF(E40<-F40,"RED FLAG",IF(E40<0,"WATCH","CLEAR")) -> CLEAR | I40: YoY asset-turnover decline >15%
A41: Hindustan Unilever | B41: Interest Coverage | C41: ='Ratio Comparison'!F65 -> 40.97006 | D41: ='Ratio Comparison'!E65 -> 40.540785 | E41: =C41 -> 40.97006 | F41: 5 | G41: < threshold | H41: =IF(C41<F41,"RED FLAG","CLEAR") -> CLEAR | I41: Interest coverage below 5x
A42: Britannia Industries | B42: Interest Coverage | C42: ='Ratio Comparison'!F66 -> 30.288288 | D42: ='Ratio Comparison'!E66 -> 22.471014 | E42: =C42 -> 30.288288 | F42: 5 | G42: < threshold | H42: =IF(C42<F42,"RED FLAG","CLEAR") -> CLEAR | I42: Interest coverage below 5x
...
